Workbook

Sheet README
A1: SARS-CoV-2 Genomic Surveillance Tracker - Western Visayas
A2: Cleaned and reorganised from COVID_SampleTracker_CLEANED.xlsx on 12 August 2026. The original file was not modified.
A5: SHEET GUIDE
A6: Run_Summary | B6: One row per sequencing run: dates, instrument, sample counts and upload status. The operational master table.
A7: Program_Metrics | B7: Surveillance coverage against reported cases, plus samples sequenced per year (calculated live from Run_Summary).
A8: Lineage_by_Run_v4.1.3 | B8: Run x Pango lineage count matrix - the current lineage table.
A9: Lineage_by_Run_v4.3 | B9: The same matrix under Pango 4.3. Superseded; kept for traceability.
A10: EB_Report | B10: Lineage counts by run, grouped into surveillance categories (Omicron-other, hybrid VOI, hybrid VUM, others, unassigned).
A11: Sample_Registry | B11: One row per sequenced specimen: strain ID, accession, UIC code, run and whether a lineage was assigned.
A12: Samples_No_Lineage | B12: Specimens that failed lineage assignment.
A13: Patient_Metadata | B13: Demographics, collecting institution, selection criteria and Ct values for the subset of specimens with linked records.
A14: Data_Issues | B14: Everything that needs a human decision, ranked by severity. Start here.
A15: Change_Log | B15: Every change this rebuild made.
A17: THE FOUR THINGS THAT WERE MOST WRONG
A18: 1. Truncated totals | B18: Four separate SUM formulas had fallen behind the data they were meant to cover. They understated EB_Report by 411 samples and dropped 761 samples from the per-run lineage totals. All totals are now formulas that span the whole table.
A19: 2. Corrupted dates | B19: Run dates were stored as a mixture of text and serial values, and 47 had their day and month transposed by a dd/mm vs mm/dd locale mismatch. All are now real dates; the few that could not be resolved are flagged.
A20: 3. Split categories | B20: Duplicate lineage columns and rows, stray whitespace in names, and mixed capitalisation in institutions and selection criteria meant the same thing was counted under several labels. These are merged.
A21: 4. Fragile layout | B21: Summary statistics sat loose inside the data grid and section subtotals depended on hard-coded row ranges. Both are gone: data areas are now uninterrupted tables and subtotals key off an explicit Category column.
A23: CONVENTIONS
A24: Dates | B24: Real Excel dates shown as dd-mmm-yyyy, so the day and month can never be read the wrong way round.
A25: Totals | B25: Always formulas over the full data range - never typed-in numbers.
A26: Highlighting | B26: A shaded row means Review_Flag is populated on that row.
A27: Identifiers | B27: Strain IDs, PGC codes and accession numbers were never renumbered. Accessions were only stripped of stray spaces and case differences.
A28: Adding a run | B28: Insert the row above the TOTAL row in Run_Summary; every formula and the Program_Metrics year totals will pick it up automatically.

Sheet Run_Summary
A1: Run_Number | B1: Run_ID | C1: Sequencer | D1: Extraction_Number | E1: Date_Received | F1: Date_Loaded | G1: Turnaround_Days | H1: Samples_Sequenced | I1: Lineage_Assigned | J1: Lineage_Unassigned | K1: Pct_Assigned | L1: Pct_Unassigned | M1: Uploaded_GISAID | N1: Uploaded_ISLAP | O1: Comments | P1: Review_Flag
A2: 1 | B2: NS_001 | C2: NextSeq1000 | D2: 1 | F2: 44588 | G2: =IF(OR(E2="",F2=""),"",F2-E2) | H2: 93 | I2: 90 | J2: =IF(H2="","",H2-I2) | K2: =IFERROR(I2/H2,"") | L2: =IFERROR(J2/H2,"") | M2: y | N2: y
A3: 4 | B3: NS_004 | C3: NextSeq1000 | D3: 2 | E3: 44608 | F3: 44610 | G3: =IF(OR(E3="",F3=""),"",F3-E3) | H3: 90 | I3: 88 | J3: =IF(H3="","",H3-I3) | K3: =IFERROR(I3/H3,"") | L3: =IFERROR(J3/H3,"") | M3: y | N3: y
A4: 5 | B4: NS_005 | C4: NextSeq1000 | D4: 3 | E4: 44615 | F4: 44617 | G4: =IF(OR(E4="",F4=""),"",F4-E4) | H4: 80 | I4: 77 | J4: =IF(H4="","",H4-I4) | K4: =IFERROR(I4/H4,"") | L4: =IFERROR(J4/H4,"") | M4: y | N4: y
A5: 7 | B5: NS_007 | C5: NextSeq1000 | D5: 4 | E5: 44622 | F5: 44624 | G5: =IF(OR(E5="",F5=""),"",F5-E5) | H5: 84 | I5: 69 | J5: =IF(H5="","",H5-I5) | K5: =IFERROR(I5/H5,"") | L5: =IFERROR(J5/H5,"") | M5: y | N5: y
A6: 8 | B6: NS_008 | C6: NextSeq1000 | D6: 5 | E6: 44629 | F6: 44631 | G6: =IF(OR(E6="",F6=""),"",F6-E6) | H6: 26 | I6: 23 | J6: =IF(H6="","",H6-I6) | K6: =IFERROR(I6/H6,"") | L6: =IFERROR(J6/H6,"") | M6: y | N6: y
A7: 9 | B7: NS_009 | C7: NextSeq1000 | D7: 6 | E7: 44636 | F7: 44637 | G7: =IF(OR(E7="",F7=""),"",F7-E7) | H7: 18 | I7: 13 | J7: =IF(H7="","",H7-I7) | K7: =IFERROR(I7/H7,"") | L7: =IFERROR(J7/H7,"") | M7: y | N7: y
A8: 10 | B8: NS_0010 | C8: NextSeq1000 | D8: 7 | E8: 44643 | F8: 44645 | G8: =IF(OR(E8="",F8=""),"",F8-E8) | H8: 12 | I8: 9 | J8: =IF(H8="","",H8-I8) | K8: =IFERROR(I8/H8,"") | L8: =IFERROR(J8/H8,"") | M8: y | N8: y
A9: 11 | B9: NS_0011 | C9: NextSeq1000 | D9: 8, 9 | E9: 44650 | F9: 44659 | G9: =IF(OR(E9="",F9=""),"",F9-E9) | H9: 15 | I9: 13 | J9: =IF(H9="","",H9-I9) | K9: =IFERROR(I9/H9,"") | L9: =IFERROR(J9/H9,"") | M9: y | N9: y
A10: 12 | B10: IS_0011 | C10: iSeq100 | D10: 10 | E10: 44672 | F10: 44673 | G10: =IF(OR(E10="",F10=""),"",F10-E10) | H10: 6 | I10: 5 | J10: =IF(H10="","",H10-I10) | K10: =IFERROR(I10/H10,"") | L10: =IFERROR(J10/H10,"") | M10: y | N10: y
A11: 13 | B11: IS_0012 | C11: iSeq100 | D11: 11 | E11: 44679 | F11: 44680 | G11: =IF(OR(E11="",F11=""),"",F11-E11) | H11: 9 | I11: 9 | J11: =IF(H11="","",H11-I11) | K11: =IFERROR(I11/H11,"") | L11: =IFERROR(J11/H11,"") | M11: y | N11: y
A12: 14 | B12: IS_0013 | C12: iSeq100 | D12: 12 | E12: 44693 | F12: 44694 | G12: =IF(OR(E12="",F12=""),"",F12-E12) | H12: 7 | I12: 5 | J12: =IF(H12="","",H12-I12) | K12: =IFERROR(I12/H12,"") | L12: =IFERROR(J12/H12,"") | M12: y | N12: y
A13: 16 | B13: IS_0015 | C13: iSeq100 | D13: 13 | E13: 44700 | F13: 44706 | G13: =IF(OR(E13="",F13=""),"",F13-E13) | H13: 10 | I13: 9 | J13: =IF(H13="","",H13-I13) | K13: =IFERROR(I13/H13,"") | L13: =IFERROR(J13/H13,"") | M13: y | N13: y
A14: 18 | B14: IS_0016 | C14: iSeq100 | D14: 14 | E14: 44721 | F14: 44722 | G14: =IF(OR(E14="",F14=""),"",F14-E14) | H14: 13 | I14: 8 | J14: =IF(H14="","",H14-I14) | K14: =IFERROR(I14/H14,"") | L14: =IFERROR(J14/H14,"") | M14: y | N14: y
... A40: 44 | B40: IS_0019, IS_0020, IS_0021 | C40: iSeq100 | D40: 39 | E40: 44896 | F40: 44897 | G40: =IF(OR(E40="",F40=""),"",F40-E40) | H40: 62 | I40: 62 | J40: =IF(H40="","",H40-I40) | K40: =IFERROR(I40/H40,"") | L40: =IFERROR(J40/H40,"") | M40: y | N40: y
A41: 45 | B41: IS_0022 | C41: iSeq100 | D41: 40 | E41: 44902 | F41: 44904 | G41: =IF(OR(E41="",F41=""),"",F41-E41) | H41: 76 | I41: 74 | J41: =IF(H41="","",H41-I41) | K41: =IFERROR(I41/H41,"") | L41: =IFERROR(J41/H41,"") | M41: y | N41: y | O41: Please check if ISeq Run
A42: 46 | B42: IS_0023 | C42: iSeq100 | D42: 41 | E42: 44909 | F42: 44910 | G42: =IF(OR(E42="",F42=""),"",F42-E42) | H42: 27 | I42: 26 | J42: =IF(H42="","",H42-I42) | K42: =IFERROR(I42/H42,"") | L42: =IFERROR(J42/H42,"") | M42: y | N42: y
A43: 47 | B43: NS_0040 | C43: NextSeq1000 | D43: 42 | E43: 44917 | F43: 44918 | G43: =IF(OR(E43="",F43=""),"",F43-E43) | H43: 74 | I43: 74 | J43: =IF(H43="","",H43-I43) | K43: =IFERROR(I43/H43,"") | L43: =IFERROR(J43/H43,"") | M43: y | N43: y
A44: 48 | B44: IS_0026 | C44: iSeq100 | D44: 43 | E44: 44923 | F44: 44924 | G44: =IF(OR(E44="",F44=""),"",F44-E44) | H44: 24 | I44: 24 | J44: =IF(H44="","",H44-I44) | K44: =IFERROR(I44/H44,"") | L44: =IFERROR(J44/H44,"") | M44: y | N44: y
A45: 49 | B45: IS_0027 | C45: NextSeq1000 | D45: 44 | E45: 44931 | F45: 44932 | G45: =IF(OR(E45="",F45=""),"",F45-E45) | H45: 14 | I45: 14 | J45: =IF(H45="","",H45-I45) | K45: =IFERROR(I45/H45,"") | L45: =IFERROR(J45/H45,"") | M45: y | N45: y
A46: 50 | B46: IS_0028 | C46: iSeq100 | D46: 45 | E46: 44938 | F46: 44939 | G46: =IF(OR(E46="",F46=""),"",F46-E46) | H46: 27 | I46: 23 | J46: =IF(H46="","",H46-I46) | K46: =IFERROR(I46/H46,"") | L46: =IFERROR(J46/H46,"") | M46: n | N46: y
A47: 52 | B47: IS_0029 | C47: iSeq100 | D47: 46, 47 | E47: 44945 | F47: 44953 | G47: =IF(OR(E47="",F47=""),"",F47-E47) | H47: 21 | I47: 20 | J47: =IF(H47="","",H47-I47) | K47: =IFERROR(I47/H47,"") | L47: =IFERROR(J47/H47,"") | M47: n | N47: y
A48: 53 | B48: IS_0033 | C48: iSeq100 | D48: 48, 49 | E48: 44966 | F48: 44967 | G48: =IF(OR(E48="",F48=""),"",F48-E48) | H48: 14 | I48: 9 | J48: =IF(H48="","",H48-I48) | K48: =IFERROR(I48/H48,"") | L48: =IFERROR(J48/H48,"") | M48: n | N48: y
A49: 54 | B49: IS_0035 | C49: iSeq100 | D49: 50, 51 | E49: 44980 | F49: 44981 | G49: =IF(OR(E49="",F49=""),"",F49-E49) | H49: 13 | I49: 13 | J49: =IF(H49="","",H49-I49) | K49: =IFERROR(I49/H49,"") | L49: =IFERROR(J49/H49,"") | M49: n | N49: y
A50: 55 | B50: IS_0037 | C50: iSeq100 | D50: 53 | E50: 44987 | F50: 44988 | G50: =IF(OR(E50="",F50=""),"",F50-E50) | H50: 7 | I50: 7 | J50: =IF(H50="","",H50-I50) | K50: =IFERROR(I50/H50,"") | L50: =IFERROR(J50/H50,"") | M50: n | N50: y
A51: 56 | B51: IS_0039 | C51: iSeq100 | D51: 53, 54, and 55 | E51: 45008 | F51: 45009 | G51: =IF(OR(E51="",F51=""),"",F51-E51) | H51: 13 | I51: 12 | J51: =IF(H51="","",H51-I51) | K51: =IFERROR(I51/H51,"") | L51: =IFERROR(J51/H51,"") | M51: n | N51: y
A52: 57 | B52: NS_0044 | C52: NextSeq1000 | D52: 56, 57, and 58 | E52: 45030 | F52: 45031 | G52: =IF(OR(E52="",F52=""),"",F52-E52) | H52: 45 | I52: 44 | J52: =IF(H52="","",H52-I52) | K52: =IFERROR(I52/H52,"") | L52: =IFERROR(J52/H52,"") | M52: n | N52: y
A53: 58 | B53: NS_0045 | C53: NextSeq1000 | D53: 59, 60 | E53: 45074 | F53: 45075 | G53: =IF(OR(E53="",F53=""),"",F53-E53) | H53: 79 | I53: 77 | J53: =IF(H53="","",H53-I53) | K53: =IFERROR(I53/H53,"") | L53: =IFERROR(J53/H53,"") | M53: n | N53: n
... A63: 68 | B63: IS_0049 | C63: iSeq100 | D63: 71, 72 | E63: 45113 | F63: 45114 | G63: =IF(OR(E63="",F63=""),"",F63-E63) | H63: 38 | I63: 32 | J63: =IF(H63="","",H63-I63) | K63: =IFERROR(I63/H63,"") | L63: =IFERROR(J63/H63,"") | M63: n | N63: n
A64: 69 | B64: IS_0050 | C64: iSeq100 | E64: 45141 | F64: 45142 | G64: =IF(OR(E64="",F64=""),"",F64-E64) | H64: 31 | I64: 31 | J64: =IF(H64="","",H64-I64) | K64: =IFERROR(I64/H64,"") | L64: =IFERROR(J64/H64,"") | M64: n | N64: n
A65: 70 | B65: NS_0055 | C65: iSeq100 | E65: 45161 | F65: 45162 | G65: =IF(OR(E65="",F65=""),"",F65-E65) | H65: 14 | I65: 14 | J65: =IF(H65="","",H65-I65) | K65: =IFERROR(I65/H65,"") | L65: =IFERROR(J65/H65,"") | M65: n | N65: n
A66: 71 | B66: IS_0053 | C66: iSeq100 | E66: 45182 | F66: 45184 | G66: =IF(OR(E66="",F66=""),"",F66-E66) | H66: 5 | I66: 5 | J66: =IF(H66="","",H66-I66) | K66: =IFERROR(I66/H66,"") | L66: =IFERROR(J66/H66,"") | M66: n | N66: n
A67: 72 | B67: NS_0057 | C67: NextSeq1000 | E67: 45218 | F67: 45219 | G67: =IF(OR(E67="",F67=""),"",F67-E67) | H67: 33 | I67: 32 | J67: =IF(H67="","",H67-I67) | K67: =IFERROR(I67/H67,"") | L67: =IFERROR(J67/H67,"") | M67: n | N67: n
A68: 73 | B68: NS_0058 | C68: NextSeq1000 | E68: 45245 | F68: 45246 | G68: =IF(OR(E68="",F68=""),"",F68-E68) | H68: 26 | I68: 26 | J68: =IF(H68="","",H68-I68) | K68: =IFERROR(I68/H68,"") | L68: =IFERROR(J68/H68,"") | M68: n | N68: n
A69: 74 | B69: NS_0059 | C69: NextSeq1000 | E69: 45274 | F69: 45275 | G69: =IF(OR(E69="",F69=""),"",F69-E69) | H69: 83 | I69: 74 | J69: =IF(H69="","",H69-I69) | K69: =IFERROR(I69/H69,"") | L69: =IFERROR(J69/H69,"") | M69: n | N69: n
A70: 75 | B70: NS_0060 | C70: NextSeq1000 | E70: 45302 | F70: 45261 | G70: =IF(OR(E70="",F70=""),"",F70-E70) | H70: 290 | I70: 254 | J70: =IF(H70="","",H70-I70) | K70: =IFERROR(I70/H70,"") | L70: =IFERROR(J70/H70,"") | M70: n | N70: n | P70: loaded before received
A71: 76 | B71: NS_0061 | C71: NextSeq1000 | E71: 45309 | F71: 45310 | G71: =IF(OR(E71="",F71=""),"",F71-E71) | H71: 129 | I71: 115 | J71: =IF(H71="","",H71-I71) | K71: =IFERROR(I71/H71,"") | L71: =IFERROR(J71/H71,"") | M71: n | N71: n
A72: 77 | B72: NS_0062 | C72: NextSeq1000 | E72: 45360 | F72: 45359 | G72: =IF(OR(E72="",F72=""),"",F72-E72) | H72: 46 | I72: 40 | J72: =IF(H72="","",H72-I72) | K72: =IFERROR(I72/H72,"") | L72: =IFERROR(J72/H72,"") | M72: n | N72: n | P72: loaded before received
A73: 78 | B73: NS_0063 | C73: NextSeq1000 | E73: 45374 | F73: 45375 | G73: =IF(OR(E73="",F73=""),"",F73-E73) | H73: 3 | I73: 3 | J73: =IF(H73="","",H73-I73) | K73: =IFERROR(I73/H73,"") | L73: =IFERROR(J73/H73,"") | M73: n | N73: n
A74: 79 | B74: IS_0056 | C74: iSeq100 | E74: 45400 | F74: 45401 | G74: =IF(OR(E74="",F74=""),"",F74-E74) | H74: 2 | I74: 2 | J74: =IF(H74="","",H74-I74) | K74: =IFERROR(I74/H74,"") | L74: =IFERROR(J74/H74,"") | M74: n | N74: n
...

Sheet Program_Metrics
A1: Programme coverage metrics
A3: Metric | B3: Value | C3: Basis
A4: Total positive COVID-19 cases in Western Visayas (as of Dec 2022) | B4: 47463 | C4: Source figure carried over from the original tracker
A5: Samples sequenced (as of Dec 2022) | B5: 5128 | C5: Source figure carried over from the original tracker
A6: Share of positive cases sequenced (as of Dec 2022) | B6: =IFERROR(B5/B4,"") | C6: B5 / B4
A8: Samples sequenced by calendar year (live, from Run_Summary)
A9: 2022 | B9: =SUMIFS(Run_Summary!$H$2:$H$86,Run_Summary!$F$2:$F$86,">="&DATE(2022,1,1),Run_Summary!$F$2:$F$86,"<="&DATE(2022,12,31)) | C9: Runs whose Date_Loaded falls in the year
A10: 2023 | B10: =SUMIFS(Run_Summary!$H$2:$H$86,Run_Summary!$F$2:$F$86,">="&DATE(2023,1,1),Run_Summary!$F$2:$F$86,"<="&DATE(2023,12,31)) | C10: Runs whose Date_Loaded falls in the year
A11: 2024 | B11: =SUMIFS(Run_Summary!$H$2:$H$86,Run_Summary!$F$2:$F$86,">="&DATE(2024,1,1),Run_Summary!$F$2:$F$86,"<="&DATE(2024,12,31)) | C11: Runs whose Date_Loaded falls in the year
A12: 2025 | B12: =SUMIFS(Run_Summary!$H$2:$H$86,Run_Summary!$F$2:$F$86,">="&DATE(2025,1,1),Run_Summary!$F$2:$F$86,"<="&DATE(2025,12,31)) | C12: Runs whose Date_Loaded falls in the year
A13: Subtotal (runs with a load date) | B13: =SUM(B9:B12)
A14: Runs with no load date recorded | B14: =Run_Summary!H87-B13 | C14: Sequenced but not yet attributable to a year
A15: Total sequenced | B15: =B13+B14 | C15: Must equal the Run_Summary TOTAL row
A16: Run_Summary cross-check (must read 0) | B16: =B15-Run_Summary!H87

Sheet Lineage_by_Run_v4.1.3
A1: RUN | B1: B.1 | C1: B.1.1.529 | D1: B.1.351 | E1: B.1.617.2 | F1: BA.1 | G1: BA.1.1.529 | H1: BA.2 | I1: BA.2.3 | J1: BA.2.3.1 | K1: BA.2.3.2 | L1: BA.2.3.6 | M1: BA.2.3.13 | N1: BA.2.3.16 | O1: BA.2.3.20 | P1: BA.2.10.1 | Q1: BA.2.12.1 | R1: BA.2.23 | S1: BA.2.38 | T1: BA.2.40.1 | U1: BA.2.42 | V1: BA.2.75 | W1: BA.2.76 | X1: BA.2.86.1 | Y1: BA.4 | Z1: BA.4.1 | AA1: BA.4.4 | AB1: BA.5 | AC1: BA.5.1 | AD1: BA.5.1.2 | AE1: BA.5.1.5 | AF1: BA.5.1.10 | AG1: BA.5.1.22 | AH1: BA.5.2 | AI1: BA.5.2.1 | AJ1: BA.5.2.6 | AK1: BA.5.2.12 | AL1: BA.5.2.16 | AM1: BA.5.2.18 | AN1: BA.5.2.19 | AO1: BA.5.2.20 | AP1: BA.5.2.24 | AQ1: BA.5.2.25 | AR1: BA.5.2.26 | AS1: BA.5.2.27 | AT1: BA.5.2.28 | AU1: BA.5.2.31 | AV1: BA.5.3.1 | AW1: BA.5.5 | AX1: BA.5.6 | AY1: BA.5.8 | AZ1: BA.5.10 | BA1: BA.5.10.1 | BB1: BE.1 | BC1: BE.3 | BD1: BF.1 | BE1: BF.3 | BF1: BF.3.1 | BG1: BF.4 | BH1: BF.5 | BI1: BF.18 | BJ1: BF.28 | BK1: BN.1.3 | BL1: BP.1 | BM1: BQ.1 | BN1: BQ.1.1 | BO1: BQ.1.1.2 | BP1: BQ.1.12 | BQ1: BR.2 | BR1: BT.1 | BS1: CM.1 | BT1: CM.2 | BU1: CM.3 | BV1: CM.4 | BW1: CM.4.1 | BX1: CM.5 | BY1: CM.5.1 | BZ1: CM.6 | CA1: CM.8 | CB1: CM.8.1 | CC1: CM.8.1.1 | CD1: CM.8.1.2 | CE1: CM.10 | CF1: CR.1 | CG1: DF.1 | CH1: EG.1 | CI1: EG.1.6 | CJ1: EG.2 | CK1: EG.5.1 | CL1: EG.5.1.1 | CM1: EL.1 | CN1: FL.1.1 | CO1: FL.1.3 | CP1: FL.1.5.1 | CQ1: FL.2 | CR1: FL.2.1 | CS1: FL.4 | CT1: FL.5 | CU1: FL.6 | CV1: FL.10 | CW1: FL.12 | CX1: FU.2 | CY1: FU.2.1 | CZ1: FV.1 | DA1: FY.2 | DB1: FY.3 | DC1: FY.3.1 | DD1: GF.1 | DE1: GJ.1 | DF1: GJ.1.2 | DG1: GJ.1.2.2 | DH1: GJ.1.2.6 | DI1: GJ.1.2.7 | DJ1: GJ.2 | DK1: GV.1 | DL1: GW.5 | DM1: HH.2 | DN1: HK.3 | DO1: JE.1 | DP1: JE.1.1 | DQ1: JN.1 | DR1: JN.1.1 | DS1: JN.1.1.1.5 | DT1: JN.1.2 | DU1: JN.1.4 | DV1: JN.1.5 | DW1: JN.1.11 | DX1: JN.1.11.1 | DY1: JN.1.16.1 | DZ1: JN.1.18 | EA1: JN.1.18.1 | EB1: JN.1.18.2 | EC1: KH.1 | ED1: KP.1.1 | EE1: KP.1.1.1 | EF1: KP.1.1.3 | EG1: KP.1.1.5 | EH1: KP.1.2 | EI1: KP.2 | EJ1: KP.2.2 | EK1: KP.2.3 | EL1: KP.3 | EM1: KP.3.1.1 | EN1: KP.3.2 | EO1: KP.3.2.2 | EP1: KP.3.3 | EQ1: KP.4 | ER1: KP.4.1 | ES1: KP.4.1.3 | ET1: KR.1 | EU1: KR.1.1 | EV1: KR.1.2 | EW1: KS.1 | EX1: KS.1.1 | EY1: KU.2 | EZ1: LA.1 | FA1: LB.1 | FB1: LB.1.3 | FC1: LB.1.4 | FD1: LQ.1.1 | FE1: XBB | FF1: XBB.1 | FG1: XBB.1.2 | FH1: XBB.1.5 | FI1: XBB.1.5.15 | FJ1: XBB.1.5.20 | FK1: XBB.1.5.24 | FL1: XBB.1.5.28 | FM1: XBB.1.5.37 | FN1: XBB.1.5.39 | FO1: XBB.1.5.48 | FP1: XBB.1.5.51 | FQ1: XBB.1.5.89 | FR1: XBB.1.6 | FS1: XBB.1.6.2 | FT1: XBB.1.6.9 | FU1: XBB.1.9 | FV1: XBB.1.9.1 | FW1: XBB.1.9.2 | FX1: XBB.1.16 | FY1: XBB.1.16.1 | FZ1: XBB.1.16.2 | GA1: XBB.1.16.9 | GB1: XBB.1.16.15 | GC1: XBB.1.18.1 | GD1: XBB.1.22.1 | GE1: XBB.1.32 | GF1: XBB.1.32.1 | GG1: XBB.2.3 | GH1: XBB.2.3.2.3 | GI1: XBB.2.3.3 | GJ1: XBB.2.3.5 | GK1: XBB.2.3.8 | GL1: XBB.3 | GM1: XBB.5 | GN1: XBC.1 | GO1: XBJ | GP1: Total_Assigned | GQ1: No_Lineage | GR1: Total_Sequenced | GS1: Run_Note
A2: 1 | E2: 1 | F2: 2 | H2: 1 | I2: 85 | M2: 1 | GP2: =SUM(B2:GO2) | GQ2: 3 | GR2: =GP2+GQ2
A3: 4 | H3: 1 | I3: 85 | J3: 2 | GP3: =SUM(B3:GO3) | GQ3: 2 | GR3: =GP3+GQ3
A4: 5 | I4: 74 | M4: 1 | N4: 2 | GP4: =SUM(B4:GO4) | GQ4: 3 | GR4: =GP4+GQ4
A5: 7 | H5: 2 | I5: 65 | L5: 1 | N5: 1 | GP5: =SUM(B5:GO5) | GQ5: 15 | GR5: =GP5+GQ5
A6: 8 | I6: 23 | GP6: =SUM(B6:GO6) | GQ6: 3 | GR6: =GP6+GQ6
A7: 9 | E7: 1 | I7: 12 | GP7: =SUM(B7:GO7) | GQ7: 5 | GR7: =GP7+GQ7
A8: 10 | H8: 1 | I8: 7 | P8: 1 | GP8: =SUM(B8:GO8) | GQ8: 3 | GR8: =GP8+GQ8
A9: 11 | H9: 1 | I9: 12 | GP9: =SUM(B9:GO9) | GQ9: 2 | GR9: =GP9+GQ9
A10: 12 | H10: 2 | I10: 2 | K10: 1 | GP10: =SUM(B10:GO10) | GQ10: 1 | GR10: =GP10+GQ10
A11: 13 | I11: 9 | GP11: =SUM(B11:GO11) | GQ11: 0 | GR11: =GP11+GQ11
A12: 14 | E12: 1 | I12: 1 | P12: 3 | GP12: =SUM(B12:GO12) | GQ12: 2 | GR12: =GP12+GQ12
A13: 16 | I13: 2 | Q13: 7 | GP13: =SUM(B13:GO13) | GQ13: 1 | GR13: =GP13+GQ13
A14: 18 | H14: 3 | I14: 3 | Q14: 1 | AH14: 1 | GP14: =SUM(B14:GO14) | GQ14: 5 | GR14: =GP14+GQ14
A15: 19 | H15: 1 | I15: 11 | Q15: 1 | AH15: 24 | AI15: 4 | GP15: =SUM(B15:GO15) | GQ15: 0 | GR15: =GP15+GQ15
A16: 20 | E16: 1 | H16: 1 | I16: 3 | Q16: 7 | T16: 1 | Z16: 1 | AH16: 34 | AI16: 1 | AP16: 1 | AY16: 1 | GP16: =SUM(B16:GO16) | GQ16: 6 | GR16: =GP16+GQ16
A17: 21 | H17: 1 | I17: 2 | Q17: 4 | U17: 1 | AC17: 6 | AH17: 82 | AI17: 2 | AN17: 3 | AW17: 4 | AY17: 2 | BD17: 1 | GP17: =SUM(B17:GO17) | GQ17: 21 | GR17: =GP17+GQ17
A18: 22 | H18: 4 | I18: 1 | Q18: 7 | R18: 2 | AC18: 1 | AF18: 1 | AG18: 1 | AH18: 50 | AI18: 4 | BH18: 1 | GP18: =SUM(B18:GO18) | GQ18: 80 | GR18: =GP18+GQ18
A19: 23 | I19: 2 | AC19: 1 | AH19: 65 | AI19: 4 | AK19: 1 | AN19: 1 | AO19: 1 | AY19: 1 | GP19: =SUM(B19:GO19) | GQ19: 4 | GR19: =GP19+GQ19
A20: 24 | I20: 9 | Q20: 1 | Z20: 7 | AB20: 5 | AH20: 213 | AI20: 11 | BE20: 2 | GP20: =SUM(B20:GO20) | GQ20: 9 | GR20: =GP20+GQ20
A21: 25 | I21: 6 | V21: 1 | AC21: 4 | AG21: 1 | AH21: 225 | AI21: 7 | AO21: 1 | AP21: 1 | AS21: 1 | AT21: 1 | AY21: 3 | AZ21: 2 | BE21: 3 | GP21: =SUM(B21:GO21) | GQ21: 7 | GR21: =GP21+GQ21
A22: 26 | I22: 10 | Q22: 2 | T22: 1 | V22: 2 | Z22: 3 | AC22: 3 | AE22: 2 | AF22: 2 | AG22: 3 | AH22: 268 | AI22: 2 | AS22: 2 | AT22: 3 | AX22: 1 | AY22: 4 | AZ22: 8 | BH22: 1 | BJ22: 1 | GP22: =SUM(B22:GO22) | GQ22: 4 | GR22: =GP22+GQ22
A23: 27 | C23: 1 | M23: 1 | Q23: 1 | Z23: 2 | AG23: 2 | AH23: 233 | AI23: 9 | AK23: 1 | AP23: 2 | AS23: 5 | AT23: 5 | AX23: 1 | AZ23: 5 | BE23: 3 | BG23: 1 | BL23: 2 | GP23: =SUM(B23:GO23) | GQ23: 4 | GR23: =GP23+GQ23
A24: 28 | I24: 2 | O24: 1 | W24: 2 | Z24: 2 | AA24: 1 | AB24: 1 | AE24: 1 | AF24: 1 | AG24: 10 | AH24: 286 | AI24: 11 | AJ24: 1 | AP24: 1 | AS24: 4 | AT24: 1 | AU24: 1 | AY24: 1 | AZ24: 16 | BA24: 1 | GP24: =SUM(B24:GO24) | GQ24: 7 | GR24: =GP24+GQ24
A25: 29 | C25: 1 | I25: 1 | V25: 2 | W25: 1 | Y25: 1 | AC25: 4 | AF25: 1 | AG25: 7 | AH25: 252 | AI25: 14 | AJ25: 1 | AM25: 2 | AP25: 1 | AS25: 1 | AX25: 1 | AY25: 3 | AZ25: 8 | BB25: 1 | GP25: =SUM(B25:GO25) | GQ25: 6 | GR25: =GP25+GQ25
A26: 30 | H26: 2 | I26: 1 | S26: 1 | V26: 2 | W26: 1 | Z26: 1 | AC26: 2 | AD26: 1 | AF26: 1 | AG26: 2 | AH26: 174 | AI26: 3 | AJ26: 5 | AM26: 1 | AO26: 1 | AP26: 3 | AS26: 10 | AU26: 1 | AZ26: 2 | BA26: 1 | BH26: 1 | GP26: =SUM(B26:GO26) | GQ26: 13 | GR26: =GP26+GQ26
A27: 31 | O27: 1 | W27: 2 | AC27: 5 | AG27: 10 | AH27: 160 | AI27: 9 | AM27: 1 | AP27: 3 | AQ27: 1 | AS27: 3 | AZ27: 15 | BB27: 1 | BC27: 3 | BH27: 5 | GP27: =SUM(B27:GO27) | GQ27: 12 | GR27: =GP27+GQ27
A28: 32 | AD28: 2 | AH28: 106 | AI28: 6 | AK28: 1 | AL28: 1 | AP28: 6 | AR28: 1 | AX28: 1 | AZ28: 5 | BA28: 1 | BF28: 1 | GP28: =SUM(B28:GO28) | GQ28: 3 | GR28: =GP28+GQ28
A29: 33 | I29: 1 | O29: 6 | AC29: 2 | AG29: 2 | AH29: 77 | AI29: 3 | AJ29: 2 | AM29: 2 | AP29: 2 | AS29: 3 | AV29: 2 | AZ29: 5 | GP29: =SUM(B29:GO29) | GQ29: 5 | GR29: =GP29+GQ29
A30: 34 | I30: 1 | O30: 8 | AC30: 3 | AD30: 3 | AG30: 2 | AH30: 63 | AI30: 2 | AM30: 1 | AZ30: 3 | BA30: 3 | BH30: 1 | BI30: 1 | FE30: 1 | GP30: =SUM(B30:GO30) | GQ30: 9 | GR30: =GP30+GQ30
A31: 35 | C31: 1 | I31: 2 | O31: 28 | AF31: 1 | AH31: 22 | AI31: 1 | AJ31: 1 | AM31: 1 | AS31: 2 | AX31: 1 | AZ31: 1 | BA31: 3 | FE31: 3 | GN31: 2 | GP31: =SUM(B31:GO31) | GQ31: 1 | GR31: =GP31+GQ31
A32: 36 | I32: 6 | O32: 31 | AG32: 3 | AH32: 10 | AS32: 1 | AZ32: 6 | BA32: 2 | BI32: 1 | BR32: 1 | FE32: 16 | GP32: =SUM(B32:GO32) | GQ32: 1 | GR32: =GP32+GQ32
A33: 37 | H33: 1 | I33: 6 | O33: 45 | P33: 1 | AH33: 17 | AI33: 2 | AZ33: 1 | BA33: 1 | BB33: 1 | FE33: 60 | GN33: 5 | GP33: =SUM(B33:GO33) | GQ33: 11 | GR33: =GP33+GQ33
A34: 38 | B34: 1 | C34: 2 | H34: 1 | I34: 6 | O34: 65 | AH34: 5 | AI34: 1 | AJ34: 2 | AZ34: 3 | BA34: 2 | FE34: 112 | GN34: 1 | GP34: =SUM(B34:GO34) | GQ34: 23 | GR34: =GP34+GQ34
A35: 39 | C35: 1 | I35: 4 | O35: 59 | AH35: 3 | AI35: 1 | AJ35: 2 | AM35: 2 | BB35: 1 | FE35: 152 | GN35: 6 | GP35: =SUM(B35:GO35) | GQ35: 9 | GR35: =GP35+GQ35
A36: 40 | I36: 3 | O36: 31 | AJ36: 1 | BA36: 1 | FE36: 87 | GN36: 1 | GP36: =SUM(B36:GO36) | GQ36: 4 | GR36: =GP36+GQ36
A37: 41 | E37: 1 | O37: 60 | P37: 5 | R37: 8 | AH37: 1 | BA37: 1 | BS37: 4 | BT37: 6 | BU37: 3 | BY37: 2 | FE37: 89 | FF37: 1 | GM37: 1 | GN37: 3 | GP37: =SUM(B37:GO37) | GQ37: 11 | GR37: =GP37+GQ37
A38: 42 | I38: 7 | O38: 62 | P38: 1 | AH38: 1 | BS38: 3 | BT38: 6 | BU38: 7 | BV38: 5 | BX38: 2 | BY38: 2 | BZ38: 1 | CF38: 1 | FE38: 86 | GN38: 1 | GP38: =SUM(B38:GO38) | GQ38: 7 | GR38: =GP38+GQ38
A39: 43 | I39: 1 | O39: 19 | P39: 1 | BA39: 1 | BM39: 1 | BS39: 1 | BT39: 1 | BU39: 2 | BV39: 3 | BY39: 2 | FE39: 41 | GN39: 2 | GP39: =SUM(B39:GO39) | GQ39: 3 | GR39: =GP39+GQ39
A40: 44 | E40: 1 | I40: 2 | O40: 13 | BU40: 2 | BX40: 2 | FE40: 39 | FF40: 1 | GL40: 1 | GN40: 1 | GP40: =SUM(B40:GO40) | GQ40: 0 | GR40: =GP40+GQ40
...

Sheet Lineage_by_Run_v4.3
A1: SUPERSEDED - lineage calls made with Pango 4.3. Retained for traceability; use Lineage_by_Run_v4.1.3 for current reporting.
A2: RUN | B2: B.1 | C2: B.1.1.529 | D2: B.1.351 | E2: B.1.617.2 | F2: BA.1 | G2: BA.2 | H2: BA.2.3 | I2: BA.2.3.1 | J2: BA.2.3.2 | K2: BA.2.3.11 | L2: BA.2.3.16 | M2: BA.2.3.20 | N2: BA.2.10.1 | O2: BA.2.12.1 | P2: BA.2.23 | Q2: BA.2.38 | R2: BA.2.40.1 | S2: BA.2.42 | T2: BA.2.75 | U2: BA.2.76 | V2: BA.4 | W2: BA.4.1 | X2: BA.4.4 | Y2: BA.5 | Z2: BA.5.1 | AA2: BA.5.1.2 | AB2: BA.5.1.5 | AC2: BA.5.1.10 | AD2: BA.5.1.15 | AE2: BA.5.1.22 | AF2: BA.5.1.30 | AG2: BA.5.2 | AH2: BA.5.2.1 | AI2: BA.5.2.6 | AJ2: BA.5.2.12 | AK2: BA.5.2.18 | AL2: BA.5.2.19 | AM2: BA.5.2.20 | AN2: BA.5.2.24 | AO2: BA.5.2.25 | AP2: BA.5.2.27 | AQ2: BA.5.2.28 | AR2: BA.5.2.31 | AS2: BA.5.2.36 | AT2: BA.5.2.38 | AU2: BA.5.3.1 | AV2: BA.5.5 | AW2: BA.5.6 | AX2: BA.5.8 | AY2: BA.5.10 | AZ2: BA.5.10.1 | BA2: BE.1 | BB2: BE.3 | BC2: BF.1 | BD2: BF.3 | BE2: BF.3.1 | BF2: BF.4 | BG2: BF.5 | BH2: BF.15 | BI2: BF.18 | BJ2: BF.28 | BK2: BN.1.3 | BL2: BP.1 | BM2: BQ.1 | BN2: BQ.1.1 | BO2: BQ.1.1.2 | BP2: BQ.1.12 | BQ2: BR.2 | BR2: BT.1 | BS2: CM.1 | BT2: CM.2 | BU2: CM.3 | BV2: CM.4 | BW2: CM.4.1 | BX2: CM.5 | BY2: CM.5.1 | BZ2: CM.6 | CA2: CM.6.1 | CB2: CM.7 | CC2: CM.8 | CD2: CM.8.1 | CE2: CM.10 | CF2: CP.1.1 | CG2: CR.1 | CH2: DD.1 | CI2: DF.1 | CJ2: XBB | CK2: XBB.1 | CL2: XBB.1.2 | CM2: XBB.1.5 | CN2: XBB.1.9 | CO2: XBB.1.9.1 | CP2: XBB.2 | CQ2: XBB.4 | CR2: XBC.1 | CS2: XBJ | CT2: Total_Assigned | CU2: No_Lineage | CV2: Total_Sequenced | CW2: Run_Note
A3: 1 | B3: 2 | E3: 1 | H3: 86 | CT3: =SUM(B3:CS3) | CU3: 1 | CV3: =CT3+CU3
A4: 4 | G4: 1 | H4: 86 | I4: 1 | CT4: =SUM(B4:CS4) | CU4: 2 | CV4: =CT4+CU4
A5: 5 | E5: 1 | G5: 7 | H5: 38 | K5: 1 | O5: 11 | AG5: 13 | CT5: =SUM(B5:CS5) | CU5: 9 | CV5: =CT5+CU5
A6: 7 | G6: 2 | H6: 66 | L6: 1 | CT6: =SUM(B6:CS6) | CU6: 15 | CV6: =CT6+CU6
A7: 8 | H7: 23 | CT7: =SUM(B7:CS7) | CU7: 3 | CV7: =CT7+CU7
A8: 9 | E8: 1 | H8: 12 | CT8: =SUM(B8:CS8) | CU8: 5 | CV8: =CT8+CU8
A9: 10 | G9: 1 | H9: 7 | N9: 1 | CT9: =SUM(B9:CS9) | CU9: 3 | CV9: =CT9+CU9
A10: 11 | H10: 1 | O10: 1 | AG10: 11 | AH10: 1 | CT10: =SUM(B10:CS10) | CU10: 0 | CV10: =CT10+CU10
A11: 12 | H11: 1 | O11: 1 | AG11: 2 | AH11: 2 | CT11: =SUM(B11:CS11) | CU11: 0 | CV11: =CT11+CU11
A12: 13 | H12: 1 | AG12: 7 | CT12: =SUM(B12:CS12) | CU12: 1 | CV12: =CT12+CU12
A13: 14 | E13: 1 | O13: 1 | AG13: 2 | CT13: =SUM(B13:CS13) | CU13: 3 | CV13: =CT13+CU13
A14: 16 | O14: 1 | AG14: 8 | AN14: 1 | CT14: =SUM(B14:CS14) | CU14: 0 | CV14: =CT14+CU14
A15: 18 | H15: 2 | O15: 2 | AG15: 4 | AH15: 1 | CT15: =SUM(B15:CS15) | CU15: 2 | CV15: =CT15+CU15
A16: 19 | G16: 1 | H16: 2 | O16: 2 | R16: 1 | W16: 1 | AG16: 21 | AL16: 2 | AX16: 2 | CT16: =SUM(B16:CS16) | CU16: 9 | CV16: =CT16+CU16
A17: 20 | G17: 1 | S17: 2 | AD17: 2 | AG17: 36 | AH17: 2 | AL17: 1 | AV17: 4 | AX17: 1 | CT17: =SUM(B17:CS17) | CU17: 10 | CV17: =CT17+CU17
A18: 21 | O18: 8 | Z18: 4 | AD18: 5 | AG18: 97 | AH18: 1 | AL18: 1 | BC18: 1 | CT18: =SUM(B18:CS18) | CU18: 9 | CV18: =CT18+CU18
A19: 22 | G19: 4 | H19: 1 | O19: 7 | P19: 2 | Z19: 1 | AC19: 1 | AE19: 1 | AG19: 50 | AH19: 4 | BG19: 1 | CT19: =SUM(B19:CS19) | CU19: 80 | CV19: =CT19+CU19
A20: 23 | H20: 3 | O20: 1 | AG20: 62 | AH20: 6 | AP20: 1 | AX20: 1 | AY20: 1 | CT20: =SUM(B20:CS20) | CU20: 5 | CV20: =CT20+CU20 | CW20: 23 (rerun of 22, 80 unassigned)
A21: 24 | CT21: =SUM(B21:CS21) | CU21: 0 | CV21: =CT21+CU21
A22: 25 | CT22: =SUM(B22:CS22) | CU22: 0 | CV22: =CT22+CU22
A23: 26 | CT23: =SUM(B23:CS23) | CU23: 0 | CV23: =CT23+CU23
A24: 27 | CT24: =SUM(B24:CS24) | CU24: 0 | CV24: =CT24+CU24
A25: 28 | CT25: =SUM(B25:CS25) | CU25: 0 | CV25: =CT25+CU25
A26: 29 | CT26: =SUM(B26:CS26) | CU26: 0 | CV26: =CT26+CU26
A27: 30 | CT27: =SUM(B27:CS27) | CU27: 0 | CV27: =CT27+CU27
A28: 31 | CT28: =SUM(B28:CS28) | CU28: 0 | CV28: =CT28+CU28
A29: 32 | CT29: =SUM(B29:CS29) | CU29: 0 | CV29: =CT29+CU29
A30: 33 | CT30: =SUM(B30:CS30) | CU30: 0 | CV30: =CT30+CU30
A31: 34 | CT31: =SUM(B31:CS31) | CU31: 0 | CV31: =CT31+CU31
A32: 35 | CT32: =SUM(B32:CS32) | CU32: 0 | CV32: =CT32+CU32
... A67: 71 | CT67: =SUM(B67:CS67) | CU67: 0 | CV67: =CT67+CU67
A68: TOTAL | B68: =SUM(B3:B67) | C68: =SUM(C3:C67) | D68: =SUM(D3:D67) | E68: =SUM(E3:E67) | F68: =SUM(F3:F67) | G68: =SUM(G3:G67) | H68: =SUM(H3:H67) | I68: =SUM(I3:I67) | ... CV68: =SUM(CV3:CV67)
A69: % of all sequenced | B69: =IFERROR(B68/$CV$68,"") | C69: =IFERROR(C68/$CV$68,"") | D69: =IFERROR(D68/$CV$68,"") | E69: =IFERROR(E68/$CV$68,"") | F69: =IFERROR(F68/$CV$68,"") | G69: =IFERROR(G68/$CV$68,"") | H69: =IFERROR(H68/$CV$68,"") | I69: =IFERROR(I68/$CV$68,"") | ... CV69: =IFERROR(CV68/$CV$68,"")
A70: % of assigned | B70: =IFERROR(B68/$CT$68,"") | C70: =IFERROR(C68/$CT$68,"") | D70: =IFERROR(D68/$CT$68,"") | E70: =IFERROR(E68/$CT$68,"") | F70: =IFERROR(F68/$CT$68,"") | G70: =IFERROR(G68/$CT$68,"") | H70: =IFERROR(H68/$CT$68,"") | I70: =IFERROR(I68/$CT$68,"") | ... CT70: =IFERROR(CT68/$CT$68,"")

Sheet EB_Report
A1: Category | B1: Lineage | C1: Run 64 | D1: Run 65 | E1: Run 66 | F1: Run 67 | G1: Run 68 | H1: Run 69 | I1: Run 70 | J1: Run 71 | K1: Run 72 | L1: Run 73 | M1: Run 74 | N1: Run 75 | O1: Run 76 | P1: Run 77 | Q1: Run 78 | R1: Run 79 | S1: Run 80 | T1: Run 81 | U1: Run 82 | V1: Run 83 | W1: Run 84 | X1: Run 85 | Y1: Run 86 | Z1: Run 87 | AA1: Run 88 | AB1: Run 89 | AC1: Lineage_Total
A2: OMICRON-OTHER | B2: OMICRON-OTHER | K2: 1 | AC2: =SUM(C2:AB2)
A3: OMICRON-OTHER | B3: BA.1.1.529 | C3: 1 | M3: 4 | N3: 10 | O3: 1 | AC3: =SUM(C3:AB3)
A4: OMICRON-OTHER | B4: BA.2 | N4: 1 | O4: 1 | P4: 1 | AC4: =SUM(C4:AB4)
A5: OMICRON-OTHER | B5: BA.2.3 | AC5: =SUM(C5:AB5)
A6: OMICRON-OTHER | B6: BA.2.86.1 | N6: 2 | AC6: =SUM(C6:AB6)
A7: OMICRON-OTHER | B7: BA.5.10 | AC7: =SUM(C7:AB7)
A8: OMICRON-OTHER | B8: CM.10 | AC8: =SUM(C8:AB8)
A9: OMICRON-OTHER | B9: CM.4.1 | AC9: =SUM(C9:AB9)
A10: OMICRON-OTHER | B10: CM.8.1 | C10: 1 | AC10: =SUM(C10:AB10)
A11: OMICRON-OTHER | B11: CM.8.1.1 | C11: 1 | AC11: =SUM(C11:AB11)
A12: OMICRON-OTHER | B12: CM.8.1.2 | AC12: =SUM(C12:AB12)
A13: OMICRON-OTHER | B13: FK.1.1 | AC13: =SUM(C13:AB13)
A14: OMICRON-OTHER | B14: FV.1 | C14: 16 | D14: 7 | E14: 2 | F14: 4 | G14: 1 | H14: 1 | AC14: =SUM(C14:AB14)
A15: HYBRID-VOI | B15: EG.5.1.1 | K15: 1 | AC15: =SUM(C15:AB15)
A16: HYBRID-VOI | B16: FL.1.5.1 | K16: 2 | AC16: =SUM(C16:AB16)
A17: HYBRID-VOI | B17: FU.2 | C17: 1 | F17: 2 | AC17: =SUM(C17:AB17)
A18: HYBRID-VOI | B18: GF.1 | I18: 1 | J18: 1 | AC18: =SUM(C18:AB18)
A19: HYBRID-VOI | B19: GJ.1.2 | I19: 1 | J19: 1 | K19: 12 | L19: 2 | M19: 3 | AC19: =SUM(C19:AB19)
A20: HYBRID-VOI | B20: GJ.1.2.2 | K20: 4 | L20: 1 | AC20: =SUM(C20:AB20)
A21: HYBRID-VOI | B21: GJ.1.2.6 | K21: 2 | L21: 2 | AC21: =SUM(C21:AB21)
A22: HYBRID-VOI | B22: GJ.1.2.7 | K22: 1 | M22: 2 | AC22: =SUM(C22:AB22)
A23: HYBRID-VOI | B23: GV.1 | F23: 2 | I23: 1 | AC23: =SUM(C23:AB23)
A24: HYBRID-VOI | B24: GW.5 | I24: 1 | AC24: =SUM(C24:AB24)
A25: HYBRID-VOI | B25: HK.3 | K25: 1 | AC25: =SUM(C25:AB25)
A26: HYBRID-VOI | B26: JN.1 | M26: 18 | N26: 176 | O26: 100 | P26: 8 | R26: 1 | AC26: =SUM(C26:AB26)
A27: HYBRID-VOI | B27: JN.1.1 | P27: 27 | R27: 1 | AC27: =SUM(C27:AB27)
A28: HYBRID-VOI | B28: JN.1.2 | P28: 1 | AC28: =SUM(C28:AB28)
A29: HYBRID-VOI | B29: JN.1.4 | P29: 1 | AC29: =SUM(C29:AB29)
A30: HYBRID-VOI | B30: JN.1.5 | P30: 1 | AC30: =SUM(C30:AB30)
A31: HYBRID-VOI | B31: XBB.1.16 | C31: 17 | D31: 8 | E31: 15 | F31: 18 | G31: 11 | H31: 5 | I31: 5 | AC31: =SUM(C31:AB31)
A32: HYBRID-VOI | B32: XBB.1.16.1 | C32: 3 | D32: 1 | E32: 1 | F32: 7 | J32: 1 | AC32: =SUM(C32:AB32)
A33: HYBRID-VOI | B33: XBB.1.16.15 | M33: 1 | N33: 6 | AC33: =SUM(C33:AB33)
A34: HYBRID-VOI | B34: XBB.1.16.2 | C34: 1 | D34: 2 | F34: 4 | G34: 1 | H34: 1 | AC34: =SUM(C34:AB34)
A35: HYBRID-VOI | B35: XBB.1.16.9 | F35: 6 | G35: 4 | H35: 3 | L35: 1 | AC35: =SUM(C35:AB35)
A36: HYBRID-VOI | B36: XBB.1.5 | C36: 3 | AC36: =SUM(C36:AB36)
A37: HYBRID-VOI | B37: XBB.1.5.15 | F37: 1 | AC37: =SUM(C37:AB37)
A38: HYBRID-VOI | B38: XBB.1.5.20 | AC38: =SUM(C38:AB38)
A39: HYBRID-VOI | B39: XBB.1.5.28 | AC39: =SUM(C39:AB39)
A40: HYBRID-VOI | B40: XBB.1.5.31 | AC40: =SUM(C40:AB40)
...

Sheet Sample_Registry
A1: Strain_ID | B1: Accession_Number | C1: UIC_Code | D1: Run_Number | E1: Sample_Number | F1: Lineage_Assigned | G1: Review_Flag
A2: PGCV_001_0001 | B2: COVID-SNL-22-3840 | C2: ARQKTQITQS | D2: 1 | E2: 1 | F2: Yes
A3: PGCV_001_0002 | B3: COVID-SNL-22-4340 | C3: BDPPT9OY05 | D3: 1 | E3: 2 | F3: Yes
A4: PGCV_001_0003 | B4: COVID-SNL-22-5523 | C4: SVGVT8HO9L | D4: 1 | E4: 3 | F4: Yes
A5: PGCV_001_0004 | B5: COVID-SNL-22-3002 | C5: VNHEVMBWPD | D5: 1 | E5: 4 | F5: Yes
A6: PGCV_001_0005 | B6: COVID-SNL-22-3039 | C6: 156XSM82VC | D6: 1 | E6: 5 | F6: Yes
A7: PGCV_001_0006 | B7: COVID-SNL-22-4894 | C7: N2QAB3H4GB | D7: 1 | E7: 6 | F7: No
A8: PGCV_001_0007 | B8: COVID-SNL-22-3040 | C8: QLPE68OYAG | D8: 1 | E8: 7 | F8: Yes
A9: PGCV_001_0008 | B9: COVID-SNL-22-4378 | C9: PINVEILWNQ | D9: 1 | E9: 8 | F9: Yes
A10: PGCV_001_0009 | B10: COVID-SNL-22-6382 | C10: PYHN0FDJZL | D10: 1 | E10: 9 | F10: Yes
A11: PGCV_001_0010 | B11: COVID-SNL-22-6940 | C11: JUMESRYMMD | D11: 1 | E11: 10 | F11: Yes
A12: PGCV_001_0011 | B12: COVID-SNL-22-6923 | C12: VFN4ITASEJ | D12: 1 | E12: 11 | F12: Yes
A13: PGCV_001_0012 | B13: COVID-SNL-22-6463 | C13: HDLLPYB94M | D13: 1 | E13: 12 | F13: Yes
... A306: PGCV_007_0306 | B306: COVID-SNL-22-24579 | C306: 0M1UCUSARQ | D306: 7 | E306: 306 | F306: Yes
A307: PGCV_007_0307 | B307: COVID-SNL-22-24686 | C307: IDHTE6AIO4 | D307: 7 | E307: 307 | F307: No | G307: specimen also sequenced as PGCV_007_0337
A308: PGCV_007_0308 | B308: COVID-SNL-22-24687 | C308: WYNUAERIPY | D308: 7 | E308: 308 | F308: Yes
A309: PGCV_007_0309 | B309: COVID-SNL-22-24594 | C309: PSTJKHVNUU | D309: 7 | E309: 309 | F309: Yes
A310: PGCV_007_0310 | B310: COVID-SNL-22-24722 | C310: 3NXH1YQD8D | D310: 7 | E310: 310 | F310: Yes
A311: PGCV_007_0311 | B311: COVID-SNL-22-24800 | C311: YD92JVUEFE | D311: 7 | E311: 311 | F311: Yes
A312: PGCV_007_0312 | B312: COVID-SNL-22-24819 | C312: ZO5ZBC8XR8 | D312: 7 | E312: 312 | F312: No
A313: PGCV_007_0313 | B313: COVID-SNL-22-24863 | C313: BVSGD6PLEU | D313: 7 | E313: 313 | F313: Yes
A314: PGCV_007_0314 | B314: COVID-SNL-22-24966 | C314: S1RSR6HPC1 | D314: 7 | E314: 314 | F314: Yes
A315: PGCV_007_0315 | B315: COVID-SNL-22-25227 | C315: 1P4DAYLHN0 | D315: 7 | E315: 315 | F315: No
A316: PGCV_007_0316 | B316: COVID-SNL-22-25230 | C316: YMQKUL7M5B | D316: 7 | E316: 316 | F316: Yes
A317: PGCV_007_0317 | B317: COVID-SNL-22-25233 | C317: JNB8IR2YGG | D317: 7 | E317: 317 | F317: Yes
A318: PGCV_007_0318 | B318: COVID-SNL-22-25199 | C318: VNMQ7XNLV0 | D318: 7 | E318: 318 | F318: No
A319: PGCV_007_0319 | B319: COVID-SNL-22-25583 | C319: ALDRGVIM40 | D319: 7 | E319: 319 | F319: Yes
... A336: PGCV_007_0336 | B336: 578B98252 | C336: RL2A4CAUDM | D336: 7 | E336: 336 | F336: Yes
A337: PGCV_007_0337 | B337: COVID-SNL-22-24686 | C337: IDHTE6AIO4 | D337: 7 | E337: 337 | F337: Yes | G337: specimen also sequenced as PGCV_007_0307
A338: PGCV_007_0338 | B338: COVID-SNL-22-26628 | C338: UEY2RQV3LJ | D338: 7 | E338: 338 | F338: Yes
A339: PGCV_007_0339 | B339: COVID-SNL-22-26796 | C339: TLTYPLGPER | D339: 7 | E339: 339 | F339: Yes
A340: PGCV_007_0340 | B340: COVID-SNL-22-26996 | C340: AYEWA0T6DJ | D340: 7 | E340: 340 | F340: Yes
A341: PGCV_007_0341 | B341: COVID-SNL-22-27026 | C341: EBQJYZ12PU | D341: 7 | E341: 341 | F341: Yes
A342: PGCV_007_0342 | B342: COVID-SNL-22-27034 | C342: VNHEVMBWPD | D342: 7 | E342: 342 | F342: No | G342: specimen also sequenced as PGCV_007_0343
A343: PGCV_007_0343 | B343: COVID-SNL-22-27034 | C343: VNHEVMBWPD | D343: 7 | E343: 343 | F343: Yes | G343: specimen also sequenced as PGCV_007_0342
A344: PGCV_007_0344 | B344: COVID-SNL-22-27173 | C344: VGAH0EVUCO | D344: 7 | E344: 344 | F344: Yes
A345: PGCV_007_0345 | B345: COVID-SNL-22-27174 | C345: IZEM34GAOO | D345: 7 | E345: 345 | F345: Yes
A346: PGCV_007_0346 | B346: COVID-SNL-22-27348 | C346: ZPJTB1V7YP | D346: 7 | E346: 346 | F346: Yes
A347: PGCV_007_0347 | B347: COVID-SNL-22-27363 | C347: 8DHTDJ4BK3 | D347: 7 | E347: 347 | F347: Yes
A348: PGCV_007_0348 | B348: COVID-SNL-22-27397 | C348: HJN4PFQVIF | D348: 7 | E348: 348 | F348: No
...

Sheet Samples_No_Lineage
A1: Strain_ID | B1: In_Sample_Registry
A2: PGCV_001_0006 | B2: Yes
A3: PGCV_001_0042 | B3: Yes
A4: PGCV_001_0055 | B4: Yes
A5: PGCV_001_0086 | B5: Yes
A6: PGCV_004_0104 | B6: Yes
A7: PGCV_004_0127 | B7: Yes
A8: PGCV_005_0208 | B8: Yes
A9: PGCV_005_0256 | B9: Yes
A10: PGCV_005_0259 | B10: Yes
A11: PGCV_007_0276 | B11: Yes
A12: PGCV_007_0284 | B12: Yes
... A239: PGCV_0036_3516 | B239: No

Sheet Patient_Metadata
A1: PGC_Code | B1: Accession_Number | C1: Collecting_Institution | D1: Region_Code | E1: Region_Name | F1: Extraction_Number | G1: Collection_Date | H1: Age | I1: Sex | J1: Selection_Criteria | K1: Ct_ORF | L1: Ct_N | M1: Ct_E | N1: Ct_RdRp | O1: Remarks | P1: Review_Flag
A2: PGCV_0208 | C2: BALASAN RURAL HEALTH UNIT | D2: 6 | E2: Region VI (Western Visayas) | G2: 44607 | H2: 83 | I2: F | J2: Cluster
A3: PGCV_0259 | C3: CORAZON LOCSIN MONTELIBANO MEMORIAL REGIONAL HOSPITAL | D3: 6 | E3: Region VI (Western Visayas) | G3: 44241 | H3: 25 | I3: F | J3: Unknown Exposure
A4: PGCV_0284 | B4: COVID-SNL-22-23862 | C4: ST. PAUL'S HOSPITAL OF ILOILO | D4: 6 | E4: Region VI (Western Visayas) | G4: 44611 | H4: 93 | I4: M | J4: Admitted
A5: PGCV_0293 | B5: COVID-SNL-22-24110 | C5: ANGEL SALAZAR MEMORIAL GENERAL HOSPITAL | D5: 6 | E5: Region VI (Western Visayas) | G5: 44612 | H5: 7 | I5: M | J5: Admitted
A6: PGCV_0295 | B6: COVID-SNL-22-24145 | C6: WESTERN VISAYAS MEDICAL CENTER | D6: 6 | E6: Region VI (Western Visayas) | G6: 44612 | H6: 57 | I6: F | J6: Admitted
A7: PGCV_0296 | B7: COVID-SNL-22-24163 | C7: WESTERN VISAYAS MEDICAL CENTER | D7: 6 | E7: Region VI (Western Visayas) | G7: 44612 | H7: 70 | I7: F | J7: Admitted
A8: PGCV_0299 | B8: COVID-SNL-22-24203 | C8: WESTERN VISAYAS MEDICAL CENTER | D8: 6 | E8: Region VI (Western Visayas) | G8: 44613 | H8: 60 | I8: F | J8: Admitted
A9: PGCV_0300 | B9: COVID-SNL-22-24299 | C9: WESTERN VISAYAS MEDICAL CENTER | D9: 6 | E9: Region VI (Western Visayas) | G9: 44613 | H9: 19 | I9: F | J9: Cluster
A10: PGCV_0307 | B10: COVID-SNL-22-24686 | C10: WESTERN VISAYAS MEDICAL CENTER | D10: 6 | E10: Region VI (Western Visayas) | G10: 44614 | H10: 26 | I10: M | J10: Admitted
A11: PGCV_0312 | B11: COVID-SNL-22-24819 | C11: BALASAN RURAL HEALTH UNIT | D11: 6 | E11: Region VI (Western Visayas) | G11: 44614 | H11: 37 | I11: F | J11: Cluster
A12: PGCV_0315 | B12: COVID-SNL-22-25227 | C12: IVISAN RURAL HEALTH UNIT | D12: 6 | E12: Region VI (Western Visayas) | G12: 44615 | H12: 60 | I12: M | J12: Cluster
A13: PGCV_0318 | B13: COVID-SNL-22-25199 | C13: WESTERN VISAYAS MEDICAL CENTER | D13: 6 | E13: Region VI (Western Visayas) | G13: 44615 | H13: 17 | I13: M | J13: Admitted
A14: PGCV_0321 | B14: COVID-SNL-22-25688 | C14: WESTERN VISAYAS MEDICAL CENTER | D14: 6 | E14: Region VI (Western Visayas) | G14: 44616 | H14: 60 | I14: M | J14: Admitted
A15: PGCV_0342 | B15: COVID-SNL-22-27034 | C15: WESTERN VISAYAS MEDICAL CENTER | D15: 6 | E15: Region VI (Western Visayas) | G15: 44616 | H15: 35 | I15: M | J15: Admitted
A16: PGCV_0008_0349 | B16: COVID-SNL-22-27431 | C16: DR. CATALINO GALLEGO NAVA PROVINCIAL HOSPITAL | D16: 6 | E16: Region VI (Western Visayas) | F16: 5 | H16: 30 | I16: M | J16: Cluster
A17: PGCV_0008_0365 | B17: COVID-SNL-22-29070 | C17: WESTERN VISAYAS MEDICAL CENTER | D17: 6 | E17: Region VI (Western Visayas) | F17: 5 | H17: 73 | I17: F | J17: Admitted
A18: PGCV_0008_0368 | B18: COVID-SNL-22-29530 | C18: WESTERN VISAYAS MEDICAL CENTER | D18: 6 | E18: Region VI (Western Visayas) | F18: 5 | H18: 30 | I18: F | J18: Cluster
A19: PGCV_0009_0381 | B19: COVID-SNL-22-30407 | C19: BUENAVISTA EMERGENCY HOSPITAL | D19: 6 | E19: Region VI (Western Visayas) | F19: 6 | G19: 44630 | H19: 67 | I19: F | J19: Cluster
A20: PGCV_0009_0385 | B20: COVID-SNL-22-30873 | C20: BUENAVISTA RURAL HEALTH UNIT | D20: 6 | E20: Region VI (Western Visayas) | F20: 6 | G20: 44631 | H20: 58 | I20: F | J20: Cluster
A21: PGCV_0009_0386 | B21: COVID-SNL-22-30877 | C21: DR. CATALINO GALLEGO NAVA PROVINCIAL HOSPITAL | D21: 6 | E21: Region VI (Western Visayas) | F21: 6 | G21: 44631 | H21: 53 | I21: M | J21: Admitted
A22: PGCV_0009_0387 | B22: COVID-SNL-22-30878 | C22: DR. CATALINO GALLEGO NAVA PROVINCIAL HOSPITAL | D22: 6 | E22: Region VI (Western Visayas) | F22: 6 | G22: 44631 | H22: 51 | I22: F | J22: Cluster
A23: PGCV_0009_0389 | B23: COVID-SNL-22-30880 | C23: DR. CATALINO GALLEGO NAVA PROVINCIAL HOSPITAL | D23: 6 | E23: Region VI (Western Visayas) | F23: 6 | G23: 44631 | H23: 23 | I23: M | J23: Cluster
A24: PGCV_0010_0394 | B24: COVID-SNL-22-32160 | C24: BJMP-PANAY ISOLATION FACILITY | D24: 6 | E24: Region VI (Western Visayas) | F24: 7 | G24: 44635 | H24: 25 | I24: F | J24: Admitted
A25: PGCV_0010_0395 | B25: COVID-SNL-22-32220 | C25: WESTERN VISAYAS MEDICAL CENTER | D25: 6 | E25: Region VI (Western Visayas) | F25: 7 | G25: 44636 | H25: 32 | I25: F | J25: Cluster
A26: PGCV_0010_0396 | B26: COVID-SNL-22-32605 | C26: WESTERN VISAYAS MEDICAL CENTER | D26: 6 | E26: Region VI (Western Visayas) | F26: 7 | G26: 44637 | H26: 59 | I26: M | J26: Admitted
A27: PGCV_0011_0410 | B27: COVID-SNL-22-34325 | C27: REP. PEDRO G. TRONO MEMORIAL HOSPITAL | D27: 6 | E27: Region VI (Western Visayas) | F27: 9/8 | G27: 44642 | H27: 36 | I27: F | J27: Admitted | P27: extraction number auto-converted to the date 2025-09-08 - likely "8/9"
A28: PGCV_0011_0411 | B28: COVID-SNL-22-34944 | C28: ILOILO DOCTOR'S HOSPITAL, INC. | D28: 6 | E28: Region VI (Western Visayas) | F28: 9/8 | G28: 44644 | H28: 25 | I28: M | J28: Cluster | P28: extraction number auto-converted to the date 2025-09-08 - likely "8/9"
A29: PGCV_0012_0422 | B29: COVID-SNL-22-41655 | C29: WESTERN VISAYAS MEDICAL CENTER | D29: 6 | E29: Region VI (Western Visayas) | F29: 10 | G29: 44665 | H29: 0 | I29: M | J29: Admitted
A30: PGCV_0014_0435 | B30: COVID-SNL-22-45460 | C30: METRO ILOILO HOSPITAL AND MEDICAL CENTER | D30: 6 | E30: Region VI (Western Visayas) | F30: 12 | G30: 44678 | H30: 28 | I30: M | J30: Admitted | P30: criteria recorded as "Admitted*" - meaning of the asterisk unknown
A31: PGCV_0014_0436 | B31: COVID-SNL-22-46029 | C31: WESTERN VISAYAS SANITARIUM | D31: 6 | E31: Region VI (Western Visayas) | F31: 12 | G31: 44680 | H31: 35 | I31: F | J31: Cluster
A32: PGCV_0015_0442 | B32: COVID-SNL-22-48928 | C32: ST. PAUL'S HOSPITAL OF ILOILO | D32: 6 | E32: Region VI (Western Visayas) | G32: 44691 | H32: 72 | I32: M | J32: Cluster
A33: PGCV_0015_0443 | B33: COVID-SNL-22-49701 | C33: WESTERN VISAYAS MEDICAL CENTER | D33: 6 | E33: Region VI (Western Visayas) | G33: 44693 | H33: 38 | I33: M | J33: Admitted
A34: PGCV_0015_0448 | B34: MLAB172587 | C34: METRO ILOILO HOSPITAL AND MEDICAL CENTER | D34: 6 | E34: Region VI (Western Visayas) | G34: 44683 | H34: 14 | I34: M | J34: Cluster
A35: PGCV_0015_0450 | B35: MLAB173089 | C35: METRO ILOILO HOSPITAL AND MEDICAL CENTER | D35: 6 | E35: Region VI (Western Visayas) | G35: 44692 | H35: 65 | I35: F | J35: Returning Overseas Filipino
A36: PGCV_0015_0451 | B36: MLAB173090 | C36: METRO ILOILO HOSPITAL AND MEDICAL CENTER | D36: 6 | E36: Region VI (Western Visayas) | G36: 44692 | H36: 66 | I36: F | J36: Returning Overseas Filipino
A37: PGCV_0016_0444 | B37: COVID-SNL-22-49957 | C37: GUIMBAL RURAL HEALTH UNIT | D37: 6 | E37: Region VI (Western Visayas) | G37: 44694 | H37: 26 | I37: F | J37: Cluster | K37: 28.83
A38: PGCV_0016_0445 | B38: COVID-SNL-22-50135 | C38: WESTERN VISAYAS MEDICAL CENTER | D38: 6 | E38: Region VI (Western Visayas) | F38: 13 | G38: 44695 | H38: 28 | I38: F | J38: Cluster | K38: 29.7
A39: PGCV_0016_0448 | B39: MLAB172587 | C39: METRO ILOILO HOSPITAL AND MEDICAL CENTER | D39: 6 | E39: Region VI (Western Visayas) | F39: 14 | G39: 44683 | H39: 14 | I39: M | J39: Cluster | L39: 15.31 | M39: 17.69
A40: PGCV_0018_0452 | B40: COVID-SNL-22-53959 | C40: SEAMEN'S HOSPITAL ILOILO | D40: 6 | E40: Region VI (Western Visayas) | F40: 14 | G40: 44708 | H40: 50 | I40: F | J40: Cluster | K40: 16.5
...

Sheet Data_Issues
A1: Items needing a decision from the laboratory team
A3: # | B3: Sheet | C3: Location | D3: Severity | E3: Issue | F3: Action taken | G3: Resolved?
A4: 1 | B4: EB_Report | C4: original rows 50, 125, 161 | D4: Critical | E4: Section subtotals used fixed ranges (=SUM(B20:B49), =SUM(B53:B94), =SUM(B128:B131)) that were never extended as lineages were appended. HYBRID-VUM omitted 30 rows and OTHERS omitted 29, understating the grand total by 411 samples (919 reported vs 1,330 actual) | F4: Section membership is now an explicit Category column and subtotals use SUMIF, so newly added rows are always included
A5: 2 | B5: Lineage_by_Run_v4.1.3 | C5: original column GS (Total Assigned) | D5: Critical | E5: The per-run total formula was =SUM(C:FB); it stopped at column FB while lineage data ran on to column GR. 761 sequenced samples across runs 72-83 were excluded from every run total, and therefore from the percentages built on them | F5: Totals rewritten to span the full lineage range
A6: 3 | B6: Lineage_by_Run_v4.1.3 | C6: original row 82 (column totals) | D6: Critical | E6: The column total formula was =SUM(B2:B70) while run data continued to row 81, so the last 11 runs were missing from every per-lineage total | F6: Column totals rewritten to cover all run rows
A7: 4 | B7: Run_Summary | C7: original row 87 (TOTAL) | D7: Critical | E7: The grand total read =SUM(G2:G83) while runs continued to row 86, so runs 89, 90 and 91 were left out: 7,356 samples reported against 7,412 actually sequenced, and 6,890 lineage assignments against 6,940 | F7: Total rewritten to cover every run row
A8: 5 | B8: EB_Report | C8: EG.5.1.1 | D8: High | E8: Classified into more than one category (HYBRID-VOI, HYBRID-VUM), so it is counted under both headings | F8: Both rows kept - the correct category needs a decision
A9: 6 | B9: Lineage_by_Run_v4.1.3 | C9: columns CX, DL | D9: High | E9: Lineage "XBB.1" occupied 2 separate columns, so its counts were split and any per-lineage lookup returned only part of the total | F9: Columns merged into one and the counts added together
A10: 7 | B10: Lineage_by_Run_v4.1.3 | C10: columns DE, DX | D10: High | E10: Lineage "XBB.1.22.1" occupied 2 separate columns, so its counts were split and any per-lineage lookup returned only part of the total | F10: Columns merged into one and the counts added together
A11: 8 | B11: Lineage_by_Run_v4.1.3 | C11: columns EF, EG | D11: High | E11: Lineage "XBB.2.3.2.3" occupied 2 separate columns, so its counts were split and any per-lineage lookup returned only part of the total | F11: Columns merged into one and the counts added together
A12: 9 | B12: Patient_Metadata | C12: coverage | D12: High | E12: Only 394 specimens carry demographic metadata, against 3510 in the sample registry, so roughly 89% of sequenced samples have no linked patient record | F12: Structure preserved; back-filling is a collection exercise, not a cleaning one
A13: 10 | B13: Run_Summary | C13: Run 75 (source row 70) | D13: High | E13: The load date (2023-12-01) precedes the receipt date (2024-01-11); one of the two is wrong and it cannot be resolved from the surrounding runs | F13: Left exactly as recorded - confirm against the run sheet and correct in place
A14: 11 | B14: Run_Summary | C14: Run 77 (source row 72) | D14: High | E14: The load date (2024-03-08) precedes the receipt date (2024-03-09); one of the two is wrong and it cannot be resolved from the surrounding runs | F14: Left exactly as recorded - confirm against the run sheet and correct in place
A15: 12 | B15: EB_Report | C15: HYBRID-VUM / XBB.1.22.1 | D15: Medium | E15: The same lineage was listed on two separate rows in one category, splitting its counts | F15: Rows merged and the counts added together
... A30: 27 | B30: Sample_Registry | C30: Strain_ID format | D30: Low | E30: The run segment is zero-padded inconsistently ({3: 391, 4: 3117} = digit-count: number of IDs), so IDs do not sort correctly as text | F30: IDs left untouched because they are external identifiers; a numeric Run_Number column was added for sorting and joins

Sheet Change_Log
A1: What this rebuild changed
A3: # | B3: Area | C3: Change
A4: 1 | B4: Run_Summary | C4: Repaired 47 day/month-transposed dates caused by a dd/mm vs mm/dd locale mismatch; each was resolved against the surrounding run timeline
A5: 2 | B5: Run_Summary | C5: Normalised ISLAP upload flags to lower-case y/n
A6: 3 | B6: Run_Summary | C6: Normalised ISLAP upload flags to lower-case y/n
A7: 4 | B7: Run_Summary | C7: Normalised ISLAP upload flags to lower-case y/n
A8: 5 | B8: Run_Summary | C8: Normalised ISLAP upload flags to lower-case y/n
A9: 6 | B9: Run_Summary | C9: Normalised ISLAP upload flags to lower-case y/n
A10: 7 | B10: Run_Summary | C10: Normalised ISLAP upload flags to lower-case y/n
A11: 8 | B11: Run_Summary | C11: Normalised ISLAP upload flags to lower-case y/n
A12: 9 | B12: Run_Summary | C12: Normalised ISLAP upload flags to lower-case y/n
A13: 10 | B13: Run_Summary | C13: Normalised ISLAP upload flags to lower-case y/n
A14: 11 | B14: Run_Summary | C14: Normalised ISLAP upload flags to lower-case y/n
A15: 12 | B15: Run_Summary | C15: Normalised ISLAP upload flags to lower-case y/n
... A34: 31 | B34: Patient_Metadata | C34: Removed 607 empty rows below the data and added an explicit Region_Name for the numeric region code
